<?xml version="1.0"?>
<robot xmlns:xacro="http://www.ros.org/wiki/xacro">

    <xacro:property name="robo_parameters" value="$(find diff_drive)/config/robo_parameters.yaml" />
    <xacro:property name="props" value="${load_yaml(robo_parameters)}"/>
    <xacro:property name="wheel_radius" value="${props['wheel_radius']}" />
    <xacro:property name="wheel_length" value="${props['wheel_length']}" />
    <xacro:property name="wheel_mass" value="${props['wheel_mass']}" />
    <xacro:property name="caster_radius" value="${props['caster_radius']}" />

    <xacro:macro name="link_wheel" params="name">
        <link name="${name}">
              <xacro:cylinder_inertia mass="${wheel_mass}" r="${wheel_radius}" l="${wheel_length}"/>
            <collision name="${name}__collision">
              <origin rpy="0 1.5707 1.5707" xyz="0 0 0"/>
              <geometry>
                <cylinder length="${wheel_length}" radius="${wheel_radius}"/>
              </geometry>
            </collision>
            <visual name="${name}_visual">
              <origin rpy="0 1.5707 1.5707" xyz="0 0 0"/>
              <geometry>
                <cylinder length="${wheel_length}" radius="${wheel_radius}"/>
              </geometry>
            </visual>
        </link>
    </xacro:macro>
    
    <xacro:macro name="joint_wheel" params="name child origin_xyz">
      <joint name="${name}" type="continuous">
        <origin rpy="0 0 0" xyz="${origin_xyz}"/>
        <child link="${child}"/>
        <parent link="link_chassis"/>
        <axis rpy="0 0 0" xyz="0 1 0"/>
        <limit effort="10000" velocity="1000"/>
        <joint_properties damping="1.0" friction="1.0"/>
      </joint>
    </xacro:macro>



    <xacro:macro name="caster" params="name z" >
        <collision name="${name}_collision">
        <origin rpy=" 0 0 0" xyz="0.35 0 ${z}"/>
        <geometry>
          <sphere radius="${caster_radius}"/>
        </geometry>

      </collision>
      <visual name="${name}_visual">
        <origin rpy=" 0 0 0" xyz="0.2 0 ${z}"/>
        <geometry>
          <sphere radius="${caster_radius}"/>
        </geometry>
      </visual>
    </xacro:macro>
    
    <xacro:macro name="cylinder_inertia" params="mass r l">
      <inertial>
        <mass value="${mass}"/>
        <origin rpy="0 1.5707 1.5707" xyz="0 0 0"/>
        <inertia  ixx="${mass*(3*r*r+l*l)/12}" ixy = "0" ixz = "0"
                  iyy="${mass*(3*r*r+l*l)/12}" iyz = "0"
                  izz="${mass*(r*r)/2}" />
      </inertial>

    </xacro:macro>

    <xacro:macro name="cube_inertia" params="mass h w d ">
        <inertial>
          <mass value="0.5"/>
          <origin rpy="0 0 0" xyz="0 0 0"/>
          <inertia ixx="0.022776" ixy="0" ixz="0" iyy="0.061176" iyz="0" izz="0.0816"/>
          <!-- <inertia  ixx="${mass*(w*w + d*d)/12}" ixy = "0" ixz = "0"
                    iyy="${mass*(h*h + d*d)/12}" iyz = "0"
                    izz="${mass*(h*h + w*w)/12}" /> -->
        </inertial>
    </xacro:macro>
</robot>




<!-- cube inertia  -->
<!-- 2.88*(0.3*0.3+0.07*0.07)/12 xx -->
<!-- 2.88*(0.5*0.5+0.07*0.07)/12 yy -->
<!-- 2.88*(0.5*0.5+0.3*0.3)/12   zz-->

<!-- cylinder inertia  -->
<!-- wheel_radius: 0.1 -->
<!-- wheel_length: 0.04 -->
<!-- wheel_mass : 0.2 -->
<!-- 0.2*(3*0.1*0.1+0.04*0.04)/12 -->
<!-- 0.2*(3*0.1*0.1+0.04*0.04)/12 -->
<!-- 0.2*(0.1*0.1)/2 -->