<?xml version="1.0"?>
<robot xmlns:xacro="http://www.ros.org/wiki/xacro">

    <xacro:property name="robo_parameters" value="$(find diff_drive)/config/robo_parameters.yaml" />
    <xacro:property name="props" value="${load_yaml(robo_parameters)}"/>
    <xacro:property name="wheel_radius" value="${props['wheel_radius']}" />
    <xacro:property name="wheel_length" value="${props['wheel_length']}" />
    <xacro:property name="wheel_mass" value="${props['wheel_mass']}" />

    <xacro:macro name="link_wheel" params="name">
        <link name="${name}">
            <inertial>
              <mass value="${wheel_mass}"/>
              <origin rpy="0 1.5707 1.5707" xyz="0 0 0"/>
              <inertia ixx="0.000526666666667" ixy="0" ixz="0" iyy="0.000526666666667" iyz="0" izz="0.001"/>
            </inertial>
            <collision name="link_right_wheel_collision">
              <origin rpy="0 1.5707 1.5707" xyz="0 0 0"/>
              <geometry>
                <cylinder length="${wheel_length}" radius="${wheel_radius}"/>
              </geometry>
            </collision>
            <visual name="${name}_visual">
              <origin rpy="0 1.5707 1.5707" xyz="0 0 0"/>
              <geometry>
                <cylinder length="${wheel_length}" radius="${wheel_radius}"/>
              </geometry>
            </visual>
        </link>
    </xacro:macro>
    
    <xacro:macro name="joint_wheel" params="name child origin_xyz">
      <joint name="${name}" type="continuous">
        <origin rpy="0 0 0" xyz="${origin_xyz}"/>
        <child link="${child}"/>
        <parent link="link_chassis"/>
        <axis rpy="0 0 0" xyz="0 1 0"/>
        <limit effort="10000" velocity="1000"/>
        <joint_properties damping="1.0" friction="1.0"/>
      </joint>
    </xacro:macro>
    
    <xacro:macro name="cylinder_inertia" params="mass r l">
      <inertia  ixx="${mass*(3*r*r+l*l)/12}" ixy = "0" ixz = "0"
                iyy="${mass*(3*r*r+l*l)/12}" iyz = "0"
                izz="${mass*(r*r)/2}" />
    </xacro:macro>
</robot>